Workbook

Sheet E418_des
A1: WT=E418 | B1: PHD50 | C1: size | D1: kd | E1: flexibility | F1: polarity | G1: alpha | H1: beta | I1: bulkiness | J1: surf | K1: h_do | L1: h_ac | M1: b_turn | N1: coil
A2: E | B2: 7.1547037 | C2: =IF(A2="G",size!$B$2,IF(A2="A",size!$B$3,IF(A2="S",size!$B$4,IF(A2="C",size!$B$5,IF(A2="D",size!$B$6,IF(A2="P",size!$B$7,IF(A2="N",size!$B$8,IF(A2="T",size!$B$9,IF(A2="E",size!$B$10,IF(A2="V",size!$B$11,IF(A2="Q",size!$B$12,IF(A2="H",size!$B$13,IF(A2="M",size!$B$14,IF(A2="I",size!$B$15,IF(A2="L",size!$B$16,IF(A2="K",size!$B$17,IF(A2="R",size!$B$18,IF(A2="F",size!$B$19,IF(A2="Y",size!$B$20,IF(A2="W",size!B21,"Please enter the one-letter code of the residue in column A")))))))))))))))))))) -> 138.4 | D2: =IF($A2="G",kd!$B$2,IF($A2="A",kd!$B$3,IF($A2="S",kd!$B$4,IF($A2="C",kd!$B$5,IF($A2="D",kd!$B$6,IF($A2="P",kd!$B$7,IF($A2="N",kd!$B$8,IF($A2="T",kd!$B$9,IF($A2="E",kd!$B$10,IF($A2="V",kd!$B$11,IF($A2="Q",kd!$B$12,IF($A2="H",kd!$B$13,IF($A2="M",kd!$B$14,IF($A2="I",kd!$B$15,IF($A2="L",kd!$B$16,IF($A2="K",kd!$B$17,IF($A2="R",kd!$B$18,IF($A2="F",kd!$B$19,IF($A2="Y",kd!$B$20,IF($A2="W",kd!C21,"Please enter the one-letter code of the residue in column A")))))))))))))))))))) -> -3.5 | E2: =IF($A2="G",flxb!$B$2,IF($A2="A",flxb!$B$3,IF($A2="S",flxb!$B$4,IF($A2="C",flxb!$B$5,IF($A2="D",flxb!$B$6,IF($A2="P",flxb!$B$7,IF($A2="N",flxb!$B$8,IF($A2="T",flxb!$B$9,IF($A2="E",flxb!$B$10,IF($A2="V",flxb!$B$11,IF($A2="Q",flxb!$B$12,IF($A2="H",flxb!$B$13,IF($A2="M",flxb!$B$14,IF($A2="I",flxb!$B$15,IF($A2="L",flxb!$B$16,IF($A2="K",flxb!$B$17,IF($A2="R",flxb!$B$18,IF($A2="F",flxb!$B$19,IF($A2="Y",flxb!$B$20,IF($A2="W",flxb!D21,"Please enter the one-letter code of the residue in column A")))))))))))))))))))) -> 0.5 | F2: =IF($A2="G",pol!$B$2,IF($A2="A",pol!$B$3,IF($A2="S",pol!$B$4,IF($A2="C",pol!$B$5,IF($A2="D",pol!$B$6,IF($A2="P",pol!$B$7,IF($A2="N",pol!$B$8,IF($A2="T",pol!$B$9,IF($A2="E",pol!$B$10,IF($A2="V",pol!$B$11,IF($A2="Q",pol!$B$12,IF($A2="H",pol!$B$13,IF($A2="M",pol!$B$14,IF($A2="I",pol!$B$15,IF($A2="L",pol!$B$16,IF($A2="K",pol!$B$17,IF($A2="R",pol!$B$18,IF($A2="F",pol!$B$19,IF($A2="Y",pol!$B$20,IF($A2="W",pol!E21,"Please enter the one-letter code of the residue in column A")))))))))))))))))))) -> 12.3 | G2: =IF($A2="G",alpha_hx!$B$2,IF($A2="A",alpha_hx!$B$3,IF($A2="S",alpha_hx!$B$4,IF($A2="C",alpha_hx!$B$5,IF($A2="D",alpha_hx!$B$6,IF($A2="P",alpha_hx!$B$7,IF($A2="N",alpha_hx!$B$8,IF($A2="T",alpha_hx!$B$9,IF($A2="E",alpha_hx!$B$10,IF($A2="V",alpha_hx!$B$11,IF($A2="Q",alpha_hx!$B$12,IF($A2="H",alpha_hx!$B$13,IF($A2="M",alpha_hx!$B$14,IF($A2="I",alpha_hx!$B$15,IF($A2="L",alpha_hx!$B$16,IF($A2="K",alpha_hx!$B$17,IF($A2="R",alpha_hx!$B$18,IF($A2="F",alpha_hx!$B$19,IF($A2="Y",alpha_hx!$B$20,IF($A2="W",alpha_hx!F21,"Please enter the one-letter code of the residue in column A")))))))))))))))))))) -> 1.504 | H2: =IF($A2="G",beta!$B$2,IF($A2="A",beta!$B$3,IF($A2="S",beta!$B$4,IF($A2="C",beta!$B$5,IF($A2="D",beta!$B$6,IF($A2="P",beta!$B$7,IF($A2="N",beta!$B$8,IF($A2="T",beta!$B$9,IF($A2="E",beta!$B$10,IF($A2="V",beta!$B$11,IF($A2="Q",beta!$B$12,IF($A2="H",beta!$B$13,IF($A2="M",beta!$B$14,IF($A2="I",beta!$B$15,IF($A2="L",beta!$B$16,IF($A2="K",beta!$B$17,IF($A2="R",beta!$B$18,IF($A2="F",beta!$B$19,IF($A2="Y",beta!$B$20,IF($A2="W",beta!G21,"Please enter the one-letter code of the residue in column A")))))))))))))))))))) -> 0.567 | I2: =IF($A2="G",bulky!$B$2,IF($A2="A",bulky!$B$3,IF($A2="S",bulky!$B$4,IF($A2="C",bulky!$B$5,IF($A2="D",bulky!$B$6,IF($A2="P",bulky!$B$7,IF($A2="N",bulky!$B$8,IF($A2="T",bulky!$B$9,IF($A2="E",bulky!$B$10,IF($A2="V",bulky!$B$11,IF($A2="Q",bulky!$B$12,IF($A2="H",bulky!$B$13,IF($A2="M",bulky!$B$14,IF($A2="I",bulky!$B$15,IF($A2="L",bulky!$B$16,IF($A2="K",bulky!$B$17,IF($A2="R",bulky!$B$18,IF($A2="F",bulky!$B$19,IF($A2="Y",bulky!$B$20,IF($A2="W",bulky!H21,"Please enter the one-letter code of the residue in column A")))))))))))))))))))) -> 13.57 | J2: =IF($A2="G",surf!$B$2,IF($A2="A",surf!$B$3,IF($A2="S",surf!$B$4,IF($A2="C",surf!$B$5,IF($A2="D",surf!$B$6,IF($A2="P",surf!$B$7,IF($A2="N",surf!$B$8,IF($A2="T",surf!$B$9,IF($A2="E",surf!$B$10,IF($A2="V",surf!$B$11,IF($A2="Q",surf!$B$12,IF($A2="H",surf!$B$13,IF($A2="M",surf!$B$14,IF($A2="I",surf!$B$15,IF($A2="L",surf!$B$16,IF($A2="K",surf!$B$17,IF($A2="R",surf!$B$18,IF($A2="F",surf!$B$19,IF($A2="Y",surf!$B$20,IF($A2="W",surf!I21,"Please enter the one-letter code of the residue in column A")))))))))))))))))))) -> 190 | K2: =IF($A2="G",h_do!$B$2,IF($A2="A",h_do!$B$3,IF($A2="S",h_do!$B$4,IF($A2="C",h_do!$B$5,IF($A2="D",h_do!$B$6,IF($A2="P",h_do!$B$7,IF($A2="N",h_do!$B$8,IF($A2="T",h_do!$B$9,IF($A2="E",h_do!$B$10,IF($A2="V",h_do!$B$11,IF($A2="Q",h_do!$B$12,IF($A2="H",h_do!$B$13,IF($A2="M",h_do!$B$14,IF($A2="I",h_do!$B$15,IF($A2="L",h_do!$B$16,IF($A2="K",h_do!$B$17,IF($A2="R",h_do!$B$18,IF($A2="F",h_do!$B$19,IF($A2="Y",h_do!$B$20,IF($A2="W",h_do!J21,"Please enter the one-letter code of the residue in column A")))))))))))))))))))) -> 0 | L2: =IF($A2="G",h_ac!$B$2,IF($A2="A",h_ac!$B$3,IF($A2="S",h_ac!$B$4,IF($A2="C",h_ac!$B$5,IF($A2="D",h_ac!$B$6,IF($A2="P",h_ac!$B$7,IF($A2="N",h_ac!$B$8,IF($A2="T",h_ac!$B$9,IF($A2="E",h_ac!$B$10,IF($A2="V",h_ac!$B$11,IF($A2="Q",h_ac!$B$12,IF($A2="H",h_ac!$B$13,IF($A2="M",h_ac!$B$14,IF($A2="I",h_ac!$B$15,IF($A2="L",h_ac!$B$16,IF($A2="K",h_ac!$B$17,IF($A2="R",h_ac!$B$18,IF($A2="F",h_ac!$B$19,IF($A2="Y",h_ac!$B$20,IF($A2="W",h_ac!K21,"Please enter the one-letter code of the residue in column A")))))))))))))))))))) -> 4 | M2: =IF($A2="G",b_turn!$B$2,IF($A2="A",b_turn!$B$3,IF($A2="S",b_turn!$B$4,IF($A2="C",b_turn!$B$5,IF($A2="D",b_turn!$B$6,IF($A2="P",b_turn!$B$7,IF($A2="N",b_turn!$B$8,IF($A2="T",b_turn!$B$9,IF($A2="E",b_turn!$B$10,IF($A2="V",b_turn!$B$11,IF($A2="Q",b_turn!$B$12,IF($A2="H",b_turn!$B$13,IF($A2="M",b_turn!$B$14,IF($A2="I",b_turn!$B$15,IF($A2="L",b_turn!$B$16,IF($A2="K",b_turn!$B$17,IF($A2="R",b_turn!$B$18,IF($A2="F",b_turn!$B$19,IF($A2="Y",b_turn!$B$20,IF($A2="W",b_turn!L21,"Please enter the one-letter code of the residue in column A")))))))))))))))))))) -> 1.149 | N2: =IF($A2="G",coil!$B$2,IF($A2="A",coil!$B$3,IF($A2="S",coil!$B$4,IF($A2="C",coil!$B$5,IF($A2="D",coil!$B$6,IF($A2="P",coil!$B$7,IF($A2="N",coil!$B$8,IF($A2="T",coil!$B$9,IF($A2="E",coil!$B$10,IF($A2="V",coil!$B$11,IF($A2="Q",coil!$B$12,IF($A2="H",coil!$B$13,IF($A2="M",coil!$B$14,IF($A2="I",coil!$B$15,IF($A2="L",coil!$B$16,IF($A2="K",coil!$B$17,IF($A2="R",coil!$B$18,IF($A2="F",coil!$B$19,IF($A2="Y",coil!$B$20,IF($A2="W",coil!M21,"Please enter the one-letter code of the residue in column A")))))))))))))))))))) -> 0.761
A3: Q | B3: 7.0444444 | C3: =IF(A3="G",size!$B$2,IF(A3="A",size!$B$3,IF(A3="S",size!$B$4,IF(A3="C",size!$B$5,IF(A3="D",size!$B$6,IF(A3="P",size!$B$7,IF(A3="N",size!$B$8,IF(A3="T",size!$B$9,IF(A3="E",size!$B$10,IF(A3="V",size!$B$11,IF(A3="Q",size!$B$12,IF(A3="H",size!$B$13,IF(A3="M",size!$B$14,IF(A3="I",size!$B$15,IF(A3="L",size!$B$16,IF(A3="K",size!$B$17,IF(A3="R",size!$B$18,IF(A3="F",size!$B$19,IF(A3="Y",size!$B$20,IF(A3="W",size!B22,"Please enter the one-letter code of the residue in column A")))))))))))))))))))) -> 143.8 | D3: =IF($A3="G",kd!$B$2,IF($A3="A",kd!$B$3,IF($A3="S",kd!$B$4,IF($A3="C",kd!$B$5,IF($A3="D",kd!$B$6,IF($A3="P",kd!$B$7,IF($A3="N",kd!$B$8,IF($A3="T",kd!$B$9,IF($A3="E",kd!$B$10,IF($A3="V",kd!$B$11,IF($A3="Q",kd!$B$12,IF($A3="H",kd!$B$13,IF($A3="M",kd!$B$14,IF($A3="I",kd!$B$15,IF($A3="L",kd!$B$16,IF($A3="K",kd!$B$17,IF($A3="R",kd!$B$18,IF($A3="F",kd!$B$19,IF($A3="Y",kd!$B$20,IF($A3="W",kd!C22,"Please enter the one-letter code of the residue in column A")))))))))))))))))))) -> -3.5 | E3: =IF($A3="G",flxb!$B$2,IF($A3="A",flxb!$B$3,IF($A3="S",flxb!$B$4,IF($A3="C",flxb!$B$5,IF($A3="D",flxb!$B$6,IF($A3="P",flxb!$B$7,IF($A3="N",flxb!$B$8,IF($A3="T",flxb!$B$9,IF($A3="E",flxb!$B$10,IF($A3="V",flxb!$B$11,IF($A3="Q",flxb!$B$12,IF($A3="H",flxb!$B$13,IF($A3="M",flxb!$B$14,IF($A3="I",flxb!$B$15,IF($A3="L",flxb!$B$16,IF($A3="K",flxb!$B$17,IF($A3="R",flxb!$B$18,IF($A3="F",flxb!$B$19,IF($A3="Y",flxb!$B$20,IF($A3="W",flxb!D22,"Please enter the one-letter code of the residue in column A")))))))))))))))))))) -> 0.49 | F3: =IF($A3="G",pol!$B$2,IF($A3="A",pol!$B$3,IF($A3="S",pol!$B$4,IF($A3="C",pol!$B$5,IF($A3="D",pol!$B$6,IF($A3="P",pol!$B$7,IF($A3="N",pol!$B$8,IF($A3="T",pol!$B$9,IF($A3="E",pol!$B$10,IF($A3="V",pol!$B$11,IF($A3="Q",pol!$B$12,IF($A3="H",pol!$B$13,IF($A3="M",pol!$B$14,IF($A3="I",pol!$B$15,IF($A3="L",pol!$B$16,IF($A3="K",pol!$B$17,IF($A3="R",pol!$B$18,IF($A3="F",pol!$B$19,IF($A3="Y",pol!$B$20,IF($A3="W",pol!E22,"Please enter the one-letter code of the residue in column A")))))))))))))))))))) -> 10.5 | G3: =IF($A3="G",alpha_hx!$B$2,IF($A3="A",alpha_hx!$B$3,IF($A3="S",alpha_hx!$B$4,IF($A3="C",alpha_hx!$B$5,IF($A3="D",alpha_hx!$B$6,IF($A3="P",alpha_hx!$B$7,IF($A3="N",alpha_hx!$B$8,IF($A3="T",alpha_hx!$B$9,IF($A3="E",alpha_hx!$B$10,IF($A3="V",alpha_hx!$B$11,IF($A3="Q",alpha_hx!$B$12,IF($A3="H",alpha_hx!$B$13,IF($A3="M",alpha_hx!$B$14,IF($A3="I",alpha_hx!$B$15,IF($A3="L",alpha_hx!$B$16,IF($A3="K",alpha_hx!$B$17,IF($A3="R",alpha_hx!$B$18,IF($A3="F",alpha_hx!$B$19,IF($A3="Y",alpha_hx!$B$20,IF($A3="W",alpha_hx!F22,"Please enter the one-letter code of the residue in column A")))))))))))))))))))) -> 1.164 | H3: =IF($A3="G",beta!$B$2,IF($A3="A",beta!$B$3,IF($A3="S",beta!$B$4,IF($A3="C",beta!$B$5,IF($A3="D",beta!$B$6,IF($A3="P",beta!$B$7,IF($A3="N",beta!$B$8,IF($A3="T",beta!$B$9,IF($A3="E",beta!$B$10,IF($A3="V",beta!$B$11,IF($A3="Q",beta!$B$12,IF($A3="H",beta!$B$13,IF($A3="M",beta!$B$14,IF($A3="I",beta!$B$15,IF($A3="L",beta!$B$16,IF($A3="K",beta!$B$17,IF($A3="R",beta!$B$18,IF($A3="F",beta!$B$19,IF($A3="Y",beta!$B$20,IF($A3="W",beta!G22,"Please enter the one-letter code of the residue in column A")))))))))))))))))))) -> 0.84 | I3: =IF($A3="G",bulky!$B$2,IF($A3="A",bulky!$B$3,IF($A3="S",bulky!$B$4,IF($A3="C",bulky!$B$5,IF($A3="D",bulky!$B$6,IF($A3="P",bulky!$B$7,IF($A3="N",bulky!$B$8,IF($A3="T",bulky!$B$9,IF($A3="E",bulky!$B$10,IF($A3="V",bulky!$B$11,IF($A3="Q",bulky!$B$12,IF($A3="H",bulky!$B$13,IF($A3="M",bulky!$B$14,IF($A3="I",bulky!$B$15,IF($A3="L",bulky!$B$16,IF($A3="K",bulky!$B$17,IF($A3="R",bulky!$B$18,IF($A3="F",bulky!$B$19,IF($A3="Y",bulky!$B$20,IF($A3="W",bulky!H22,"Please enter the one-letter code of the residue in column A")))))))))))))))))))) -> 14.45 | J3: =IF($A3="G",surf!$B$2,IF($A3="A",surf!$B$3,IF($A3="S",surf!$B$4,IF($A3="C",surf!$B$5,IF($A3="D",surf!$B$6,IF($A3="P",surf!$B$7,IF($A3="N",surf!$B$8,IF($A3="T",surf!$B$9,IF($A3="E",surf!$B$10,IF($A3="V",surf!$B$11,IF($A3="Q",surf!$B$12,IF($A3="H",surf!$B$13,IF($A3="M",surf!$B$14,IF($A3="I",surf!$B$15,IF($A3="L",surf!$B$16,IF($A3="K",surf!$B$17,IF($A3="R",surf!$B$18,IF($A3="F",surf!$B$19,IF($A3="Y",surf!$B$20,IF($A3="W",surf!I22,"Please enter the one-letter code of the residue in column A")))))))))))))))))))) -> 180 | K3: =IF($A3="G",h_do!$B$2,IF($A3="A",h_do!$B$3,IF($A3="S",h_do!$B$4,IF($A3="C",h_do!$B$5,IF($A3="D",h_do!$B$6,IF($A3="P",h_do!$B$7,IF($A3="N",h_do!$B$8,IF($A3="T",h_do!$B$9,IF($A3="E",h_do!$B$10,IF($A3="V",h_do!$B$11,IF($A3="Q",h_do!$B$12,IF($A3="H",h_do!$B$13,IF($A3="M",h_do!$B$14,IF($A3="I",h_do!$B$15,IF($A3="L",h_do!$B$16,IF($A3="K",h_do!$B$17,IF($A3="R",h_do!$B$18,IF($A3="F",h_do!$B$19,IF($A3="Y",h_do!$B$20,IF($A3="W",h_do!J22,"Please enter the one-letter code of the residue in column A")))))))))))))))))))) -> 2 | L3: =IF($A3="G",h_ac!$B$2,IF($A3="A",h_ac!$B$3,IF($A3="S",h_ac!$B$4,IF($A3="C",h_ac!$B$5,IF($A3="D",h_ac!$B$6,IF($A3="P",h_ac!$B$7,IF($A3="N",h_ac!$B$8,IF($A3="T",h_ac!$B$9,IF($A3="E",h_ac!$B$10,IF($A3="V",h_ac!$B$11,IF($A3="Q",h_ac!$B$12,IF($A3="H",h_ac!$B$13,IF($A3="M",h_ac!$B$14,IF($A3="I",h_ac!$B$15,IF($A3="L",h_ac!$B$16,IF($A3="K",h_ac!$B$17,IF($A3="R",h_ac!$B$18,IF($A3="F",h_ac!$B$19,IF($A3="Y",h_ac!$B$20,IF($A3="W",h_ac!K22,"Please enter the one-letter code of the residue in column A")))))))))))))))))))) -> 2 | M3: =IF($A3="G",b_turn!$B$2,IF($A3="A",b_turn!$B$3,IF($A3="S",b_turn!$B$4,IF($A3="C",b_turn!$B$5,IF($A3="D",b_turn!$B$6,IF($A3="P",b_turn!$B$7,IF($A3="N",b_turn!$B$8,IF($A3="T",b_turn!$B$9,IF($A3="E",b_turn!$B$10,IF($A3="V",b_turn!$B$11,IF($A3="Q",b_turn!$B$12,IF($A3="H",b_turn!$B$13,IF($A3="M",b_turn!$B$14,IF($A3="I",b_turn!$B$15,IF($A3="L",b_turn!$B$16,IF($A3="K",b_turn!$B$17,IF($A3="R",b_turn!$B$18,IF($A3="F",b_turn!$B$19,IF($A3="Y",b_turn!$B$20,IF($A3="W",b_turn!L22,"Please enter the one-letter code of the residue in column A")))))))))))))))))))) -> 0.997 | N3: =IF($A3="G",coil!$B$2,IF($A3="A",coil!$B$3,IF($A3="S",coil!$B$4,IF($A3="C",coil!$B$5,IF($A3="D",coil!$B$6,IF($A3="P",coil!$B$7,IF($A3="N",coil!$B$8,IF($A3="T",coil!$B$9,IF($A3="E",coil!$B$10,IF($A3="V",coil!$B$11,IF($A3="Q",coil!$B$12,IF($A3="H",coil!$B$13,IF($A3="M",coil!$B$14,IF($A3="I",coil!$B$15,IF($A3="L",coil!$B$16,IF($A3="K",coil!$B$17,IF($A3="R",coil!$B$18,IF($A3="F",coil!$B$19,IF($A3="Y",coil!$B$20,IF($A3="W",coil!M22,"Please enter the one-letter code of the residue in column A")))))))))))))))))))) -> 0.947
A4: N | B4: 7.0065455 | C4: =IF(A4="G",size!$B$2,IF(A4="A",size!$B$3,IF(A4="S",size!$B$4,IF(A4="C",size!$B$5,IF(A4="D",size!$B$6,IF(A4="P",size!$B$7,IF(A4="N",size!$B$8,IF(A4="T",size!$B$9,IF(A4="E",size!$B$10,IF(A4="V",size!$B$11,IF(A4="Q",size!$B$12,IF(A4="H",size!$B$13,IF(A4="M",size!$B$14,IF(A4="I",size!$B$15,IF(A4="L",size!$B$16,IF(A4="K",size!$B$17,IF(A4="R",size!$B$18,IF(A4="F",size!$B$19,IF(A4="Y",size!$B$20,IF(A4="W",size!B23,"Please enter the one-letter code of the residue in column A")))))))))))))))))))) -> 114.1 | D4: =IF($A4="G",kd!$B$2,IF($A4="A",kd!$B$3,IF($A4="S",kd!$B$4,IF($A4="C",kd!$B$5,IF($A4="D",kd!$B$6,IF($A4="P",kd!$B$7,IF($A4="N",kd!$B$8,IF($A4="T",kd!$B$9,IF($A4="E",kd!$B$10,IF($A4="V",kd!$B$11,IF($A4="Q",kd!$B$12,IF($A4="H",kd!$B$13,IF($A4="M",kd!$B$14,IF($A4="I",kd!$B$15,IF($A4="L",kd!$B$16,IF($A4="K",kd!$B$17,IF($A4="R",kd!$B$18,IF($A4="F",kd!$B$19,IF($A4="Y",kd!$B$20,IF($A4="W",kd!C23,"Please enter the one-letter code of the residue in column A")))))))))))))))))))) -> -3.2 | E4: =IF($A4="G",flxb!$B$2,IF($A4="A",flxb!$B$3,IF($A4="S",flxb!$B$4,IF($A4="C",flxb!$B$5,IF($A4="D",flxb!$B$6,IF($A4="P",flxb!$B$7,IF($A4="N",flxb!$B$8,IF($A4="T",flxb!$B$9,IF($A4="E",flxb!$B$10,IF($A4="V",flxb!$B$11,IF($A4="Q",flxb!$B$12,IF($A4="H",flxb!$B$13,IF($A4="M",flxb!$B$14,IF($A4="I",flxb!$B$15,IF($A4="L",flxb!$B$16,IF($A4="K",flxb!$B$17,IF($A4="R",flxb!$B$18,IF($A4="F",flxb!$B$19,IF($A4="Y",flxb!$B$20,IF($A4="W",flxb!D23,"Please enter the one-letter code of the residue in column A")))))))))))))))))))) -> 0.46 | F4: =IF($A4="G",pol!$B$2,IF($A4="A",pol!$B$3,IF($A4="S",pol!$B$4,IF($A4="C",pol!$B$5,IF($A4="D",pol!$B$6,IF($A4="P",pol!$B$7,IF($A4="N",pol!$B$8,IF($A4="T",pol!$B$9,IF($A4="E",pol!$B$10,IF($A4="V",pol!$B$11,IF($A4="Q",pol!$B$12,IF($A4="H",pol!$B$13,IF($A4="M",pol!$B$14,IF($A4="I",pol!$B$15,IF($A4="L",pol!$B$16,IF($A4="K",pol!$B$17,IF($A4="R",pol!$B$18,IF($A4="F",pol!$B$19,IF($A4="Y",pol!$B$20,IF($A4="W",pol!E23,"Please enter the one-letter code of the residue in column A")))))))))))))))))))) -> 11.6 | G4: =IF($A4="G",alpha_hx!$B$2,IF($A4="A",alpha_hx!$B$3,IF($A4="S",alpha_hx!$B$4,IF($A4="C",alpha_hx!$B$5,IF($A4="D",alpha_hx!$B$6,IF($A4="P",alpha_hx!$B$7,IF($A4="N",alpha_hx!$B$8,IF($A4="T",alpha_hx!$B$9,IF($A4="E",alpha_hx!$B$10,IF($A4="V",alpha_hx!$B$11,IF($A4="Q",alpha_hx!$B$12,IF($A4="H",alpha_hx!$B$13,IF($A4="M",alpha_hx!$B$14,IF($A4="I",alpha_hx!$B$15,IF($A4="L",alpha_hx!$B$16,IF($A4="K",alpha_hx!$B$17,IF($A4="R",alpha_hx!$B$18,IF($A4="F",alpha_hx!$B$19,IF($A4="Y",alpha_hx!$B$20,IF($A4="W",alpha_hx!F23,"Please enter the one-letter code of the residue in column A")))))))))))))))))))) -> 0.772 | H4: =IF($A4="G",beta!$B$2,IF($A4="A",beta!$B$3,IF($A4="S",beta!$B$4,IF($A4="C",beta!$B$5,IF($A4="D",beta!$B$6,IF($A4="P",beta!$B$7,IF($A4="N",beta!$B$8,IF($A4="T",beta!$B$9,IF($A4="E",beta!$B$10,IF($A4="V",beta!$B$11,IF($A4="Q",beta!$B$12,IF($A4="H",beta!$B$13,IF($A4="M",beta!$B$14,IF($A4="I",beta!$B$15,IF($A4="L",beta!$B$16,IF($A4="K",beta!$B$17,IF($A4="R",beta!$B$18,IF($A4="F",beta!$B$19,IF($A4="Y",beta!$B$20,IF($A4="W",beta!G23,"Please enter the one-letter code of the residue in column A")))))))))))))))))))) -> 0.604 | I4: =IF($A4="G",bulky!$B$2,IF($A4="A",bulky!$B$3,IF($A4="S",bulky!$B$4,IF($A4="C",bulky!$B$5,IF($A4="D",bulky!$B$6,IF($A4="P",bulky!$B$7,IF($A4="N",bulky!$B$8,IF($A4="T",bulky!$B$9,IF($A4="E",bulky!$B$10,IF($A4="V",bulky!$B$11,IF($A4="Q",bulky!$B$12,IF($A4="H",bulky!$B$13,IF($A4="M",bulky!$B$14,IF($A4="I",bulky!$B$15,IF($A4="L",bulky!$B$16,IF($A4="K",bulky!$B$17,IF($A4="R",bulky!$B$18,IF($A4="F",bulky!$B$19,IF($A4="Y",bulky!$B$20,IF($A4="W",bulky!H23,"Please enter the one-letter code of the residue in column A")))))))))))))))))))) -> 12.82 | J4: =IF($A4="G",surf!$B$2,IF($A4="A",surf!$B$3,IF($A4="S",surf!$B$4,IF($A4="C",surf!$B$5,IF($A4="D",surf!$B$6,IF($A4="P",surf!$B$7,IF($A4="N",surf!$B$8,IF($A4="T",surf!$B$9,IF($A4="E",surf!$B$10,IF($A4="V",surf!$B$11,IF($A4="Q",surf!$B$12,IF($A4="H",surf!$B$13,IF($A4="M",surf!$B$14,IF($A4="I",surf!$B$15,IF($A4="L",surf!$B$16,IF($A4="K",surf!$B$17,IF($A4="R",surf!$B$18,IF($A4="F",surf!$B$19,IF($A4="Y",surf!$B$20,IF($A4="W",surf!I23,"Please enter the one-letter code of the residue in column A")))))))))))))))))))) -> 160 | K4: =IF($A4="G",h_do!$B$2,IF($A4="A",h_do!$B$3,IF($A4="S",h_do!$B$4,IF($A4="C",h_do!$B$5,IF($A4="D",h_do!$B$6,IF($A4="P",h_do!$B$7,IF($A4="N",h_do!$B$8,IF($A4="T",h_do!$B$9,IF($A4="E",h_do!$B$10,IF($A4="V",h_do!$B$11,IF($A4="Q",h_do!$B$12,IF($A4="H",h_do!$B$13,IF($A4="M",h_do!$B$14,IF($A4="I",h_do!$B$15,IF($A4="L",h_do!$B$16,IF($A4="K",h_do!$B$17,IF($A4="R",h_do!$B$18,IF($A4="F",h_do!$B$19,IF($A4="Y",h_do!$B$20,IF($A4="W",h_do!J23,"Please enter the one-letter code of the residue in column A")))))))))))))))))))) -> 2 | L4: =IF($A4="G",h_ac!$B$2,IF($A4="A",h_ac!$B$3,IF($A4="S",h_ac!$B$4,IF($A4="C",h_ac!$B$5,IF($A4="D",h_ac!$B$6,IF($A4="P",h_ac!$B$7,IF($A4="N",h_ac!$B$8,IF($A4="T",h_ac!$B$9,IF($A4="E",h_ac!$B$10,IF($A4="V",h_ac!$B$11,IF($A4="Q",h_ac!$B$12,IF($A4="H",h_ac!$B$13,IF($A4="M",h_ac!$B$14,IF($A4="I",h_ac!$B$15,IF($A4="L",h_ac!$B$16,IF($A4="K",h_ac!$B$17,IF($A4="R",h_ac!$B$18,IF($A4="F",h_ac!$B$19,IF($A4="Y",h_ac!$B$20,IF($A4="W",h_ac!K23,"Please enter the one-letter code of the residue in column A")))))))))))))))))))) -> 2 | M4: =IF($A4="G",b_turn!$B$2,IF($A4="A",b_turn!$B$3,IF($A4="S",b_turn!$B$4,IF($A4="C",b_turn!$B$5,IF($A4="D",b_turn!$B$6,IF($A4="P",b_turn!$B$7,IF($A4="N",b_turn!$B$8,IF($A4="T",b_turn!$B$9,IF($A4="E",b_turn!$B$10,IF($A4="V",b_turn!$B$11,IF($A4="Q",b_turn!$B$12,IF($A4="H",b_turn!$B$13,IF($A4="M",b_turn!$B$14,IF($A4="I",b_turn!$B$15,IF($A4="L",b_turn!$B$16,IF($A4="K",b_turn!$B$17,IF($A4="R",b_turn!$B$18,IF($A4="F",b_turn!$B$19,IF($A4="Y",b_turn!$B$20,IF($A4="W",b_turn!L23,"Please enter the one-letter code of the residue in column A")))))))))))))))))))) -> 1.572 | N4: =IF($A4="G",coil!$B$2,IF($A4="A",coil!$B$3,IF($A4="S",coil!$B$4,IF($A4="C",coil!$B$5,IF($A4="D",coil!$B$6,IF($A4="P",coil!$B$7,IF($A4="N",coil!$B$8,IF($A4="T",coil!$B$9,IF($A4="E",coil!$B$10,IF($A4="V",coil!$B$11,IF($A4="Q",coil!$B$12,IF($A4="H",coil!$B$13,IF($A4="M",coil!$B$14,IF($A4="I",coil!$B$15,IF($A4="L",coil!$B$16,IF($A4="K",coil!$B$17,IF($A4="R",coil!$B$18,IF($A4="F",coil!$B$19,IF($A4="Y",coil!$B$20,IF($A4="W",coil!M23,"Please enter the one-letter code of the residue in column A")))))))))))))))))))) -> 1.167
A5: A | B5: 7.099 | C5: =IF(A5="G",size!$B$2,IF(A5="A",size!$B$3,IF(A5="S",size!$B$4,IF(A5="C",size!$B$5,IF(A5="D",size!$B$6,IF(A5="P",size!$B$7,IF(A5="N",size!$B$8,IF(A5="T",size!$B$9,IF(A5="E",size!$B$10,IF(A5="V",size!$B$11,IF(A5="Q",size!$B$12,IF(A5="H",size!$B$13,IF(A5="M",size!$B$14,IF(A5="I",size!$B$15,IF(A5="L",size!$B$16,IF(A5="K",size!$B$17,IF(A5="R",size!$B$18,IF(A5="F",size!$B$19,IF(A5="Y",size!$B$20,IF(A5="W",size!B24,"Please enter the one-letter code of the residue in column A")))))))))))))))))))) -> 88.6 | D5: =IF($A5="G",kd!$B$2,IF($A5="A",kd!$B$3,IF($A5="S",kd!$B$4,IF($A5="C",kd!$B$5,IF($A5="D",kd!$B$6,IF($A5="P",kd!$B$7,IF($A5="N",kd!$B$8,IF($A5="T",kd!$B$9,IF($A5="E",kd!$B$10,IF($A5="V",kd!$B$11,IF($A5="Q",kd!$B$12,IF($A5="H",kd!$B$13,IF($A5="M",kd!$B$14,IF($A5="I",kd!$B$15,IF($A5="L",kd!$B$16,IF($A5="K",kd!$B$17,IF($A5="R",kd!$B$18,IF($A5="F",kd!$B$19,IF($A5="Y",kd!$B$20,IF($A5="W",kd!C24,"Please enter the one-letter code of the residue in column A")))))))))))))))))))) -> 1.8 | E5: =IF($A5="G",flxb!$B$2,IF($A5="A",flxb!$B$3,IF($A5="S",flxb!$B$4,IF($A5="C",flxb!$B$5,IF($A5="D",flxb!$B$6,IF($A5="P",flxb!$B$7,IF($A5="N",flxb!$B$8,IF($A5="T",flxb!$B$9,IF($A5="E",flxb!$B$10,IF($A5="V",flxb!$B$11,IF($A5="Q",flxb!$B$12,IF($A5="H",flxb!$B$13,IF($A5="M",flxb!$B$14,IF($A5="I",flxb!$B$15,IF($A5="L",flxb!$B$16,IF($A5="K",flxb!$B$17,IF($A5="R",flxb!$B$18,IF($A5="F",flxb!$B$19,IF($A5="Y",flxb!$B$20,IF($A5="W",flxb!D24,"Please enter the one-letter code of the residue in column A")))))))))))))))))))) -> 0.36 | F5: =IF($A5="G",pol!$B$2,IF($A5="A",pol!$B$3,IF($A5="S",pol!$B$4,IF($A5="C",pol!$B$5,IF($A5="D",pol!$B$6,IF($A5="P",pol!$B$7,IF($A5="N",pol!$B$8,IF($A5="T",pol!$B$9,IF($A5="E",pol!$B$10,IF($A5="V",pol!$B$11,IF($A5="Q",pol!$B$12,IF($A5="H",pol!$B$13,IF($A5="M",pol!$B$14,IF($A5="I",pol!$B$15,IF($A5="L",pol!$B$16,IF($A5="K",pol!$B$17,IF($A5="R",pol!$B$18,IF($A5="F",pol!$B$19,IF($A5="Y",pol!$B$20,IF($A5="W",pol!E24,"Please enter the one-letter code of the residue in column A")))))))))))))))))))) -> 8.1 | G5: =IF($A5="G",alpha_hx!$B$2,IF($A5="A",alpha_hx!$B$3,IF($A5="S",alpha_hx!$B$4,IF($A5="C",alpha_hx!$B$5,IF($A5="D",alpha_hx!$B$6,IF($A5="P",alpha_hx!$B$7,IF($A5="N",alpha_hx!$B$8,IF($A5="T",alpha_hx!$B$9,IF($A5="E",alpha_hx!$B$10,IF($A5="V",alpha_hx!$B$11,IF($A5="Q",alpha_hx!$B$12,IF($A5="H",alpha_hx!$B$13,IF($A5="M",alpha_hx!$B$14,IF($A5="I",alpha_hx!$B$15,IF($A5="L",alpha_hx!$B$16,IF($A5="K",alpha_hx!$B$17,IF($A5="R",alpha_hx!$B$18,IF($A5="F",alpha_hx!$B$19,IF($A5="Y",alpha_hx!$B$20,IF($A5="W",alpha_hx!F24,"Please enter the one-letter code of the residue in column A")))))))))))))))))))) -> 1.489 | H5: =IF($A5="G",beta!$B$2,IF($A5="A",beta!$B$3,IF($A5="S",beta!$B$4,IF($A5="C",beta!$B$5,IF($A5="D",beta!$B$6,IF($A5="P",beta!$B$7,IF($A5="N",beta!$B$8,IF($A5="T",beta!$B$9,IF($A5="E",beta!$B$10,IF($A5="V",beta!$B$11,IF($A5="Q",beta!$B$12,IF($A5="H",beta!$B$13,IF($A5="M",beta!$B$14,IF($A5="I",beta!$B$15,IF($A5="L",beta!$B$16,IF($A5="K",beta!$B$17,IF($A5="R",beta!$B$18,IF($A5="F",beta!$B$19,IF($A5="Y",beta!$B$20,IF($A5="W",beta!G24,"Please enter the one-letter code of the residue in column A")))))))))))))))))))) -> 0.709 | I5: =IF($A5="G",bulky!$B$2,IF($A5="A",bulky!$B$3,IF($A5="S",bulky!$B$4,IF($A5="C",bulky!$B$5,IF($A5="D",bulky!$B$6,IF($A5="P",bulky!$B$7,IF($A5="N",bulky!$B$8,IF($A5="T",bulky!$B$9,IF($A5="E",bulky!$B$10,IF($A5="V",bulky!$B$11,IF($A5="Q",bulky!$B$12,IF($A5="H",bulky!$B$13,IF($A5="M",bulky!$B$14,IF($A5="I",bulky!$B$15,IF($A5="L",bulky!$B$16,IF($A5="K",bulky!$B$17,IF($A5="R",bulky!$B$18,IF($A5="F",bulky!$B$19,IF($A5="Y",bulky!$B$20,IF($A5="W",bulky!H24,"Please enter the one-letter code of the residue in column A")))))))))))))))))))) -> 11.5 | J5: =IF($A5="G",surf!$B$2,IF($A5="A",surf!$B$3,IF($A5="S",surf!$B$4,IF($A5="C",surf!$B$5,IF($A5="D",surf!$B$6,IF($A5="P",surf!$B$7,IF($A5="N",surf!$B$8,IF($A5="T",surf!$B$9,IF($A5="E",surf!$B$10,IF($A5="V",surf!$B$11,IF($A5="Q",surf!$B$12,IF($A5="H",surf!$B$13,IF($A5="M",surf!$B$14,IF($A5="I",surf!$B$15,IF($A5="L",surf!$B$16,IF($A5="K",surf!$B$17,IF($A5="R",surf!$B$18,IF($A5="F",surf!$B$19,IF($A5="Y",surf!$B$20,IF($A5="W",surf!I24,"Please enter the one-letter code of the residue in column A")))))))))))))))))))) -> 115 | K5: =IF($A5="G",h_do!$B$2,IF($A5="A",h_do!$B$3,IF($A5="S",h_do!$B$4,IF($A5="C",h_do!$B$5,IF($A5="D",h_do!$B$6,IF($A5="P",h_do!$B$7,IF($A5="N",h_do!$B$8,IF($A5="T",h_do!$B$9,IF($A5="E",h_do!$B$10,IF($A5="V",h_do!$B$11,IF($A5="Q",h_do!$B$12,IF($A5="H",h_do!$B$13,IF($A5="M",h_do!$B$14,IF($A5="I",h_do!$B$15,IF($A5="L",h_do!$B$16,IF($A5="K",h_do!$B$17,IF($A5="R",h_do!$B$18,IF($A5="F",h_do!$B$19,IF($A5="Y",h_do!$B$20,IF($A5="W",h_do!J24,"Please enter the one-letter code of the residue in column A")))))))))))))))))))) -> 0 | L5: =IF($A5="G",h_ac!$B$2,IF($A5="A",h_ac!$B$3,IF($A5="S",h_ac!$B$4,IF($A5="C",h_ac!$B$5,IF($A5="D",h_ac!$B$6,IF($A5="P",h_ac!$B$7,IF($A5="N",h_ac!$B$8,IF($A5="T",h_ac!$B$9,IF($A5="E",h_ac!$B$10,IF($A5="V",h_ac!$B$11,IF($A5="Q",h_ac!$B$12,IF($A5="H",h_ac!$B$13,IF($A5="M",h_ac!$B$14,IF($A5="I",h_ac!$B$15,IF($A5="L",h_ac!$B$16,IF($A5="K",h_ac!$B$17,IF($A5="R",h_ac!$B$18,IF($A5="F",h_ac!$B$19,IF($A5="Y",h_ac!$B$20,IF($A5="W",h_ac!K24,"Please enter the one-letter code of the residue in column A")))))))))))))))))))) -> 0 | M5: =IF($A5="G",b_turn!$B$2,IF($A5="A",b_turn!$B$3,IF($A5="S",b_turn!$B$4,IF($A5="C",b_turn!$B$5,IF($A5="D",b_turn!$B$6,IF($A5="P",b_turn!$B$7,IF($A5="N",b_turn!$B$8,IF($A5="T",b_turn!$B$9,IF($A5="E",b_turn!$B$10,IF($A5="V",b_turn!$B$11,IF($A5="Q",b_turn!$B$12,IF($A5="H",b_turn!$B$13,IF($A5="M",b_turn!$B$14,IF($A5="I",b_turn!$B$15,IF($A5="L",b_turn!$B$16,IF($A5="K",b_turn!$B$17,IF($A5="R",b_turn!$B$18,IF($A5="F",b_turn!$B$19,IF($A5="Y",b_turn!$B$20,IF($A5="W",b_turn!L24,"Please enter the one-letter code of the residue in column A")))))))))))))))))))) -> 0.788 | N5: =IF($A5="G",coil!$B$2,IF($A5="A",coil!$B$3,IF($A5="S",coil!$B$4,IF($A5="C",coil!$B$5,IF($A5="D",coil!$B$6,IF($A5="P",coil!$B$7,IF($A5="N",coil!$B$8,IF($A5="T",coil!$B$9,IF($A5="E",coil!$B$10,IF($A5="V",coil!$B$11,IF($A5="Q",coil!$B$12,IF($A5="H",coil!$B$13,IF($A5="M",coil!$B$14,IF($A5="I",coil!$B$15,IF($A5="L",coil!$B$16,IF($A5="K",coil!$B$17,IF($A5="R",coil!$B$18,IF($A5="F",coil!$B$19,IF($A5="Y",coil!$B$20,IF($A5="W",coil!M24,"Please enter the one-letter code of the residue in column A")))))))))))))))))))) -> 0.824
A6: D | B6: 6.8357273 | C6: =IF(A6="G",size!$B$2,IF(A6="A",size!$B$3,IF(A6="S",size!$B$4,IF(A6="C",size!$B$5,IF(A6="D",size!$B$6,IF(A6="P",size!$B$7,IF(A6="N",size!$B$8,IF(A6="T",size!$B$9,IF(A6="E",size!$B$10,IF(A6="V",size!$B$11,IF(A6="Q",size!$B$12,IF(A6="H",size!$B$13,IF(A6="M",size!$B$14,IF(A6="I",size!$B$15,IF(A6="L",size!$B$16,IF(A6="K",size!$B$17,IF(A6="R",size!$B$18,IF(A6="F",size!$B$19,IF(A6="Y",size!$B$20,IF(A6="W",size!B25,"Please enter the one-letter code of the residue in column A")))))))))))))))))))) -> 111.1 | D6: =IF($A6="G",kd!$B$2,IF($A6="A",kd!$B$3,IF($A6="S",kd!$B$4,IF($A6="C",kd!$B$5,IF($A6="D",kd!$B$6,IF($A6="P",kd!$B$7,IF($A6="N",kd!$B$8,IF($A6="T",kd!$B$9,IF($A6="E",kd!$B$10,IF($A6="V",kd!$B$11,IF($A6="Q",kd!$B$12,IF($A6="H",kd!$B$13,IF($A6="M",kd!$B$14,IF($A6="I",kd!$B$15,IF($A6="L",kd!$B$16,IF($A6="K",kd!$B$17,IF($A6="R",kd!$B$18,IF($A6="F",kd!$B$19,IF($A6="Y",kd!$B$20,IF($A6="W",kd!C25,"Please enter the one-letter code of the residue in column A")))))))))))))))))))) -> -3.5 | E6: =IF($A6="G",flxb!$B$2,IF($A6="A",flxb!$B$3,IF($A6="S",flxb!$B$4,IF($A6="C",flxb!$B$5,IF($A6="D",flxb!$B$6,IF($A6="P",flxb!$B$7,IF($A6="N",flxb!$B$8,IF($A6="T",flxb!$B$9,IF($A6="E",flxb!$B$10,IF($A6="V",flxb!$B$11,IF($A6="Q",flxb!$B$12,IF($A6="H",flxb!$B$13,IF($A6="M",flxb!$B$14,IF($A6="I",flxb!$B$15,IF($A6="L",flxb!$B$16,IF($A6="K",flxb!$B$17,IF($A6="R",flxb!$B$18,IF($A6="F",flxb!$B$19,IF($A6="Y",flxb!$B$20,IF($A6="W",flxb!D25,"Please enter the one-letter code of the residue in column A")))))))))))))))))))) -> 0.51 | F6: =IF($A6="G",pol!$B$2,IF($A6="A",pol!$B$3,IF($A6="S",pol!$B$4,IF($A6="C",pol!$B$5,IF($A6="D",pol!$B$6,IF($A6="P",pol!$B$7,IF($A6="N",pol!$B$8,IF($A6="T",pol!$B$9,IF($A6="E",pol!$B$10,IF($A6="V",pol!$B$11,IF($A6="Q",pol!$B$12,IF($A6="H",pol!$B$13,IF($A6="M",pol!$B$14,IF($A6="I",pol!$B$15,IF($A6="L",pol!$B$16,IF($A6="K",pol!$B$17,IF($A6="R",pol!$B$18,IF($A6="F",pol!$B$19,IF($A6="Y",pol!$B$20,IF($A6="W",pol!E25,"Please enter the one-letter code of the residue in column A")))))))))))))))))))) -> 13 | G6: =IF($A6="G",alpha_hx!$B$2,IF($A6="A",alpha_hx!$B$3,IF($A6="S",alpha_hx!$B$4,IF($A6="C",alpha_hx!$B$5,IF($A6="D",alpha_hx!$B$6,IF($A6="P",alpha_hx!$B$7,IF($A6="N",alpha_hx!$B$8,IF($A6="T",alpha_hx!$B$9,IF($A6="E",alpha_hx!$B$10,IF($A6="V",alpha_hx!$B$11,IF($A6="Q",alpha_hx!$B$12,IF($A6="H",alpha_hx!$B$13,IF($A6="M",alpha_hx!$B$14,IF($A6="I",alpha_hx!$B$15,IF($A6="L",alpha_hx!$B$16,IF($A6="K",alpha_hx!$B$17,IF($A6="R",alpha_hx!$B$18,IF($A6="F",alpha_hx!$B$19,IF($A6="Y",alpha_hx!$B$20,IF($A6="W",alpha_hx!F25,"Please enter the one-letter code of the residue in column A")))))))))))))))))))) -> 0.924 | H6: =IF($A6="G",beta!$B$2,IF($A6="A",beta!$B$3,IF($A6="S",beta!$B$4,IF($A6="C",beta!$B$5,IF($A6="D",beta!$B$6,IF($A6="P",beta!$B$7,IF($A6="N",beta!$B$8,IF($A6="T",beta!$B$9,IF($A6="E",beta!$B$10,IF($A6="V",beta!$B$11,IF($A6="Q",beta!$B$12,IF($A6="H",beta!$B$13,IF($A6="M",beta!$B$14,IF($A6="I",beta!$B$15,IF($A6="L",beta!$B$16,IF($A6="K",beta!$B$17,IF($A6="R",beta!$B$18,IF($A6="F",beta!$B$19,IF($A6="Y",beta!$B$20,IF($A6="W",beta!G25,"Please enter the one-letter code of the residue in column A")))))))))))))))))))) -> 0.541 | I6: =IF($A6="G",bulky!$B$2,IF($A6="A",bulky!$B$3,IF($A6="S",bulky!$B$4,IF($A6="C",bulky!$B$5,IF($A6="D",bulky!$B$6,IF($A6="P",bulky!$B$7,IF($A6="N",bulky!$B$8,IF($A6="T",bulky!$B$9,IF($A6="E",bulky!$B$10,IF($A6="V",bulky!$B$11,IF($A6="Q",bulky!$B$12,IF($A6="H",bulky!$B$13,IF($A6="M",bulky!$B$14,IF($A6="I",bulky!$B$15,IF($A6="L",bulky!$B$16,IF($A6="K",bulky!$B$17,IF($A6="R",bulky!$B$18,IF($A6="F",bulky!$B$19,IF($A6="Y",bulky!$B$20,IF($A6="W",bulky!H25,"Please enter the one-letter code of the residue in column A")))))))))))))))))))) -> 11.68 | J6: =IF($A6="G",surf!$B$2,IF($A6="A",surf!$B$3,IF($A6="S",surf!$B$4,IF($A6="C",surf!$B$5,IF($A6="D",surf!$B$6,IF($A6="P",surf!$B$7,IF($A6="N",surf!$B$8,IF($A6="T",surf!$B$9,IF($A6="E",surf!$B$10,IF($A6="V",surf!$B$11,IF($A6="Q",surf!$B$12,IF($A6="H",surf!$B$13,IF($A6="M",surf!$B$14,IF($A6="I",surf!$B$15,IF($A6="L",surf!$B$16,IF($A6="K",surf!$B$17,IF($A6="R",surf!$B$18,IF($A6="F",surf!$B$19,IF($A6="Y",surf!$B$20,IF($A6="W",surf!I25,"Please enter the one-letter code of the residue in column A")))))))))))))))))))) -> 150 | K6: =IF($A6="G",h_do!$B$2,IF($A6="A",h_do!$B$3,IF($A6="S",h_do!$B$4,IF($A6="C",h_do!$B$5,IF($A6="D",h_do!$B$6,IF($A6="P",h_do!$B$7,IF($A6="N",h_do!$B$8,IF($A6="T",h_do!$B$9,IF($A6="E",h_do!$B$10,IF($A6="V",h_do!$B$11,IF($A6="Q",h_do!$B$12,IF($A6="H",h_do!$B$13,IF($A6="M",h_do!$B$14,IF($A6="I",h_do!$B$15,IF($A6="L",h_do!$B$16,IF($A6="K",h_do!$B$17,IF($A6="R",h_do!$B$18,IF($A6="F",h_do!$B$19,IF($A6="Y",h_do!$B$20,IF($A6="W",h_do!J25,"Please enter the one-letter code of the residue in column A")))))))))))))))))))) -> 0 | L6: =IF($A6="G",h_ac!$B$2,IF($A6="A",h_ac!$B$3,IF($A6="S",h_ac!$B$4,IF($A6="C",h_ac!$B$5,IF($A6="D",h_ac!$B$6,IF($A6="P",h_ac!$B$7,IF($A6="N",h_ac!$B$8,IF($A6="T",h_ac!$B$9,IF($A6="E",h_ac!$B$10,IF($A6="V",h_ac!$B$11,IF($A6="Q",h_ac!$B$12,IF($A6="H",h_ac!$B$13,IF($A6="M",h_ac!$B$14,IF($A6="I",h_ac!$B$15,IF($A6="L",h_ac!$B$16,IF($A6="K",h_ac!$B$17,IF($A6="R",h_ac!$B$18,IF($A6="F",h_ac!$B$19,IF($A6="Y",h_ac!$B$20,IF($A6="W",h_ac!K25,"Please enter the one-letter code of the residue in column A")))))))))))))))))))) -> 4 | M6: =IF($A6="G",b_turn!$B$2,IF($A6="A",b_turn!$B$3,IF($A6="S",b_turn!$B$4,IF($A6="C",b_turn!$B$5,IF($A6="D",b_turn!$B$6,IF($A6="P",b_turn!$B$7,IF($A6="N",b_turn!$B$8,IF($A6="T",b_turn!$B$9,IF($A6="E",b_turn!$B$10,IF($A6="V",b_turn!$B$11,IF($A6="Q",b_turn!$B$12,IF($A6="H",b_turn!$B$13,IF($A6="M",b_turn!$B$14,IF($A6="I",b_turn!$B$15,IF($A6="L",b_turn!$B$16,IF($A6="K",b_turn!$B$17,IF($A6="R",b_turn!$B$18,IF($A6="F",b_turn!$B$19,IF($A6="Y",b_turn!$B$20,IF($A6="W",b_turn!L25,"Please enter the one-letter code of the residue in column A")))))))))))))))))))) -> 1.197 | N6: =IF($A6="G",coil!$B$2,IF($A6="A",coil!$B$3,IF($A6="S",coil!$B$4,IF($A6="C",coil!$B$5,IF($A6="D",coil!$B$6,IF($A6="P",coil!$B$7,IF($A6="N",coil!$B$8,IF($A6="T",coil!$B$9,IF($A6="E",coil!$B$10,IF($A6="V",coil!$B$11,IF($A6="Q",coil!$B$12,IF($A6="H",coil!$B$13,IF($A6="M",coil!$B$14,IF($A6="I",coil!$B$15,IF($A6="L",coil!$B$16,IF($A6="K",coil!$B$17,IF($A6="R",coil!$B$18,IF($A6="F",coil!$B$19,IF($A6="Y",coil!$B$20,IF($A6="W",coil!M25,"Please enter the one-letter code of the residue in column A")))))))))))))))))))) -> 1.197
A7: R | B7: 7.1074138 | C7: =IF(A7="G",size!$B$2,IF(A7="A",size!$B$3,IF(A7="S",size!$B$4,IF(A7="C",size!$B$5,IF(A7="D",size!$B$6,IF(A7="P",size!$B$7,IF(A7="N",size!$B$8,IF(A7="T",size!$B$9,IF(A7="E",size!$B$10,IF(A7="V",size!$B$11,IF(A7="Q",size!$B$12,IF(A7="H",size!$B$13,IF(A7="M",size!$B$14,IF(A7="I",size!$B$15,IF(A7="L",size!$B$16,IF(A7="K",size!$B$17,IF(A7="R",size!$B$18,IF(A7="F",size!$B$19,IF(A7="Y",size!$B$20,IF(A7="W",size!B26,"Please enter the one-letter code of the residue in column A")))))))))))))))))))) -> 173.4 | D7: =IF($A7="G",kd!$B$2,IF($A7="A",kd!$B$3,IF($A7="S",kd!$B$4,IF($A7="C",kd!$B$5,IF($A7="D",kd!$B$6,IF($A7="P",kd!$B$7,IF($A7="N",kd!$B$8,IF($A7="T",kd!$B$9,IF($A7="E",kd!$B$10,IF($A7="V",kd!$B$11,IF($A7="Q",kd!$B$12,IF($A7="H",kd!$B$13,IF($A7="M",kd!$B$14,IF($A7="I",kd!$B$15,IF($A7="L",kd!$B$16,IF($A7="K",kd!$B$17,IF($A7="R",kd!$B$18,IF($A7="F",kd!$B$19,IF($A7="Y",kd!$B$20,IF($A7="W",kd!C26,"Please enter the one-letter code of the residue in column A")))))))))))))))))))) -> -4.5 | E7: =IF($A7="G",flxb!$B$2,IF($A7="A",flxb!$B$3,IF($A7="S",flxb!$B$4,IF($A7="C",flxb!$B$5,IF($A7="D",flxb!$B$6,IF($A7="P",flxb!$B$7,IF($A7="N",flxb!$B$8,IF($A7="T",flxb!$B$9,IF($A7="E",flxb!$B$10,IF($A7="V",flxb!$B$11,IF($A7="Q",flxb!$B$12,IF($A7="H",flxb!$B$13,IF($A7="M",flxb!$B$14,IF($A7="I",flxb!$B$15,IF($A7="L",flxb!$B$16,IF($A7="K",flxb!$B$17,IF($A7="R",flxb!$B$18,IF($A7="F",flxb!$B$19,IF($A7="Y",flxb!$B$20,IF($A7="W",flxb!D26,"Please enter the one-letter code of the residue in column A")))))))))))))))))))) -> 0.53 | F7: =IF($A7="G",pol!$B$2,IF($A7="A",pol!$B$3,IF($A7="S",pol!$B$4,IF($A7="C",pol!$B$5,IF($A7="D",pol!$B$6,IF($A7="P",pol!$B$7,IF($A7="N",pol!$B$8,IF($A7="T",pol!$B$9,IF($A7="E",pol!$B$10,IF($A7="V",pol!$B$11,IF($A7="Q",pol!$B$12,IF($A7="H",pol!$B$13,IF($A7="M",pol!$B$14,IF($A7="I",pol!$B$15,IF($A7="L",pol!$B$16,IF($A7="K",pol!$B$17,IF($A7="R",pol!$B$18,IF($A7="F",pol!$B$19,IF($A7="Y",pol!$B$20,IF($A7="W",pol!E26,"Please enter the one-letter code of the residue in column A")))))))))))))))))))) -> 10.5 | G7: =IF($A7="G",alpha_hx!$B$2,IF($A7="A",alpha_hx!$B$3,IF($A7="S",alpha_hx!$B$4,IF($A7="C",alpha_hx!$B$5,IF($A7="D",alpha_hx!$B$6,IF($A7="P",alpha_hx!$B$7,IF($A7="N",alpha_hx!$B$8,IF($A7="T",alpha_hx!$B$9,IF($A7="E",alpha_hx!$B$10,IF($A7="V",alpha_hx!$B$11,IF($A7="Q",alpha_hx!$B$12,IF($A7="H",alpha_hx!$B$13,IF($A7="M",alpha_hx!$B$14,IF($A7="I",alpha_hx!$B$15,IF($A7="L",alpha_hx!$B$16,IF($A7="K",alpha_hx!$B$17,IF($A7="R",alpha_hx!$B$18,IF($A7="F",alpha_hx!$B$19,IF($A7="Y",alpha_hx!$B$20,IF($A7="W",alpha_hx!F26,"Please enter the one-letter code of the residue in column A")))))))))))))))))))) -> 1.224 | H7: =IF($A7="G",beta!$B$2,IF($A7="A",beta!$B$3,IF($A7="S",beta!$B$4,IF($A7="C",beta!$B$5,IF($A7="D",beta!$B$6,IF($A7="P",beta!$B$7,IF($A7="N",beta!$B$8,IF($A7="T",beta!$B$9,IF($A7="E",beta!$B$10,IF($A7="V",beta!$B$11,IF($A7="Q",beta!$B$12,IF($A7="H",beta!$B$13,IF($A7="M",beta!$B$14,IF($A7="I",beta!$B$15,IF($A7="L",beta!$B$16,IF($A7="K",beta!$B$17,IF($A7="R",beta!$B$18,IF($A7="F",beta!$B$19,IF($A7="Y",beta!$B$20,IF($A7="W",beta!G26,"Please enter the one-letter code of the residue in column A")))))))))))))))))))) -> 0.92 | I7: =IF($A7="G",bulky!$B$2,IF($A7="A",bulky!$B$3,IF($A7="S",bulky!$B$4,IF($A7="C",bulky!$B$5,IF($A7="D",bulky!$B$6,IF($A7="P",bulky!$B$7,IF($A7="N",bulky!$B$8,IF($A7="T",bulky!$B$9,IF($A7="E",bulky!$B$10,IF($A7="V",bulky!$B$11,IF($A7="Q",bulky!$B$12,IF($A7="H",bulky!$B$13,IF($A7="M",bulky!$B$14,IF($A7="I",bulky!$B$15,IF($A7="L",bulky!$B$16,IF($A7="K",bulky!$B$17,IF($A7="R",bulky!$B$18,IF($A7="F",bulky!$B$19,IF($A7="Y",bulky!$B$20,IF($A7="W",bulky!H26,"Please enter the one-letter code of the residue in column A")))))))))))))))))))) -> 14.28 | J7: =IF($A7="G",surf!$B$2,IF($A7="A",surf!$B$3,IF($A7="S",surf!$B$4,IF($A7="C",surf!$B$5,IF($A7="D",surf!$B$6,IF($A7="P",surf!$B$7,IF($A7="N",surf!$B$8,IF($A7="T",surf!$B$9,IF($A7="E",surf!$B$10,IF($A7="V",surf!$B$11,IF($A7="Q",surf!$B$12,IF($A7="H",surf!$B$13,IF($A7="M",surf!$B$14,IF($A7="I",surf!$B$15,IF($A7="L",surf!$B$16,IF($A7="K",surf!$B$17,IF($A7="R",surf!$B$18,IF($A7="F",surf!$B$19,IF($A7="Y",surf!$B$20,IF($A7="W",surf!I26,"Please enter the one-letter code of the residue in column A")))))))))))))))))))) -> 225 | K7: =IF($A7="G",h_do!$B$2,IF($A7="A",h_do!$B$3,IF($A7="S",h_do!$B$4,IF($A7="C",h_do!$B$5,IF($A7="D",h_do!$B$6,IF($A7="P",h_do!$B$7,IF($A7="N",h_do!$B$8,IF($A7="T",h_do!$B$9,IF($A7="E",h_do!$B$10,IF($A7="V",h_do!$B$11,IF($A7="Q",h_do!$B$12,IF($A7="H",h_do!$B$13,IF($A7="M",h_do!$B$14,IF($A7="I",h_do!$B$15,IF($A7="L",h_do!$B$16,IF($A7="K",h_do!$B$17,IF($A7="R",h_do!$B$18,IF($A7="F",h_do!$B$19,IF($A7="Y",h_do!$B$20,IF($A7="W",h_do!J26,"Please enter the one-letter code of the residue in column A")))))))))))))))))))) -> 5 | L7: =IF($A7="G",h_ac!$B$2,IF($A7="A",h_ac!$B$3,IF($A7="S",h_ac!$B$4,IF($A7="C",h_ac!$B$5,IF($A7="D",h_ac!$B$6,IF($A7="P",h_ac!$B$7,IF($A7="N",h_ac!$B$8,IF($A7="T",h_ac!$B$9,IF($A7="E",h_ac!$B$10,IF($A7="V",h_ac!$B$11,IF($A7="Q",h_ac!$B$12,IF($A7="H",h_ac!$B$13,IF($A7="M",h_ac!$B$14,IF($A7="I",h_ac!$B$15,IF($A7="L",h_ac!$B$16,IF($A7="K",h_ac!$B$17,IF($A7="R",h_ac!$B$18,IF($A7="F",h_ac!$B$19,IF($A7="Y",h_ac!$B$20,IF($A7="W",h_ac!K26,"Please enter the one-letter code of the residue in column A")))))))))))))))))))) -> 0 | M7: =IF($A7="G",b_turn!$B$2,IF($A7="A",b_turn!$B$3,IF($A7="S",b_turn!$B$4,IF($A7="C",b_turn!$B$5,IF($A7="D",b_turn!$B$6,IF($A7="P",b_turn!$B$7,IF($A7="N",b_turn!$B$8,IF($A7="T",b_turn!$B$9,IF($A7="E",b_turn!$B$10,IF($A7="V",b_turn!$B$11,IF($A7="Q",b_turn!$B$12,IF($A7="H",b_turn!$B$13,IF($A7="M",b_turn!$B$14,IF($A7="I",b_turn!$B$15,IF($A7="L",b_turn!$B$16,IF($A7="K",b_turn!$B$17,IF($A7="R",b_turn!$B$18,IF($A7="F",b_turn!$B$19,IF($A7="Y",b_turn!$B$20,IF($A7="W",b_turn!L26,"Please enter the one-letter code of the residue in column A")))))))))))))))))))) -> 0.912 | N7: =IF($A7="G",coil!$B$2,IF($A7="A",coil!$B$3,IF($A7="S",coil!$B$4,IF($A7="C",coil!$B$5,IF($A7="D",coil!$B$6,IF($A7="P",coil!$B$7,IF($A7="N",coil!$B$8,IF($A7="T",coil!$B$9,IF($A7="E",coil!$B$10,IF($A7="V",coil!$B$11,IF($A7="Q",coil!$B$12,IF($A7="H",coil!$B$13,IF($A7="M",coil!$B$14,IF($A7="I",coil!$B$15,IF($A7="L",coil!$B$16,IF($A7="K",coil!$B$17,IF($A7="R",coil!$B$18,IF($A7="F",coil!$B$19,IF($A7="Y",coil!$B$20,IF($A7="W",coil!M26,"Please enter the one-letter code of the residue in column A")))))))))))))))))))) -> 0.893
A14: ###############################################################################################################################################
A15: mean | B15: =AVERAGE(B2:B13) -> 7.0413058 | C15: =AVERAGE(C2:C13) -> 128.23333 | D15: =AVERAGE(D2:D13) -> -2.7333333 | E15: =AVERAGE(E2:E13) -> 0.475 | F15: =AVERAGE(F2:F13) -> 11 | G15: =AVERAGE(G2:G13) -> 1.1795 | H15: =AVERAGE(H2:H13) -> 0.69683333 | I15: =AVERAGE(I2:I13) -> 13.05 | ... N15: =AVERAGE(N2:N13) -> 0.96483333
A16: stdev | B16: =STDEV(B2:B13) -> 0.11317123 | C16: =STDEV(C2:C13) -> 29.832242 | D16: =STDEV(D2:D13) -> 2.2650975 | E16: =STDEV(E2:E13) -> 0.060909769 | F16: =STDEV(F2:F13) -> 1.7297399 | G16: =STDEV(G2:G13) -> 0.29483809 | H16: =STDEV(H2:H13) -> 0.15505279 | I16: =STDEV(I2:I13) -> 1.2708737 | ... N16: =STDEV(N2:N13) -> 0.1797959
A18: Correlation | C18: =CORREL($B2:$B13,C2:C13) -> 0.3503709 | D18: =CORREL($B2:$B13,D2:D13) -> 0.17885605 | E18: =CORREL($B2:$B13,E2:E13) -> -0.19702537 | F18: =CORREL($B2:$B13,F2:F13) -> -0.49707854 | G18: =CORREL($B2:$B13,G2:G13) -> 0.74466737 | H18: =CORREL($B2:$B13,H2:H13) -> 0.41538047 | I18: =CORREL($B2:$B13,I2:I13) -> 0.47958572 | J18: =CORREL($B2:$B13,J2:J13) -> 0.33985872 | ... N18: =CORREL($B2:$B13,N2:N13) -> -0.89248445
A19: slope | C19: =SLOPE(C2:C13, $B2:$B13) -> 92.358715 | D19: =SLOPE(D2:D13, $B2:$B13) -> 3.5797649 | E19: =SLOPE(E2:E13, $B2:$B13) -> -0.10604082 | F19: =SLOPE(F2:F13, $B2:$B13) -> -7.5974836 | G19: =SLOPE(G2:G13, $B2:$B13) -> 1.9400364 | H19: =SLOPE(H2:H13, $B2:$B13) -> 0.56910135 | I19: =SLOPE(I2:I13, $B2:$B13) -> 5.3855815 | J19: =SLOPE(J2:J13, $B2:$B13) -> 112.76438 | ... N19: =SLOPE(N2:N13, $B2:$B13) -> -1.4178961
A20: intercept | C20: =INTERCEPT(C2:C13, $B2:$B13) -> -522.09262 | D20: =INTERCEPT(D2:D13, $B2:$B13) -> -27.939553 | E20: =INTERCEPT(E2:E13, $B2:$B13) -> 1.2216658 | F20: =INTERCEPT(F2:F13, $B2:$B13) -> 64.496205 | G20: =INTERCEPT(G2:G13, $B2:$B13) -> -12.48089 | H20: =INTERCEPT(H2:H13, $B2:$B13) -> -3.3103833 | I20: =INTERCEPT(I2:I13, $B2:$B13) -> -24.871526 | J20: =INTERCEPT(J2:J13, $B2:$B13) -> -624.00848 | ... N20: =INTERCEPT(N2:N13, $B2:$B13) -> 10.948673
A21: r2 | C21: =RSQ(C2:C13, $B2:$B13) -> 0.12275976 | D21: =RSQ(D2:D13, $B2:$B13) -> 0.031989488 | E21: =RSQ(E2:E13, $B2:$B13) -> 0.038818997 | F21: =RSQ(F2:F13, $B2:$B13) -> 0.24708707 | G21: =RSQ(G2:G13, $B2:$B13) -> 0.55452949 | H21: =RSQ(H2:H13, $B2:$B13) -> 0.17254093 | I21: =RSQ(I2:I13, $B2:$B13) -> 0.23000246 | J21: =RSQ(J2:J13, $B2:$B13) -> 0.11550395 | ... N21: =RSQ(N2:N13, $B2:$B13) -> 0.7965285
A22: n | C22: =COUNT($B2:$B13) -> 6 | D22: =COUNT($B2:$B13) -> 6 | E22: =COUNT($B2:$B13) -> 6 | F22: =COUNT($B2:$B13) -> 6 | G22: =COUNT($B2:$B13) -> 6 | H22: =COUNT($B2:$B13) -> 6 | I22: =COUNT($B2:$B13) -> 6 | J22: =COUNT($B2:$B13) -> 6 | ... N22: =COUNT($B2:$B13) -> 6
A23: df | C23: =C22-2 -> 4 | D23: =D22-2 -> 4 | E23: =E22-2 -> 4 | F23: =F22-2 -> 4 | G23: =G22-2 -> 4 | H23: =H22-2 -> 4 | I23: =I22-2 -> 4 | J23: =J22-2 -> 4 | ... N23: =N22-2 -> 4
A24: t_stat | C24: =SLOPE(C2:C13,$B2:$B13)/(STEYX(C2:C13,$B2:$B13)/SQRT(DEVSQ($B2:$B13))) -> 0.74816734 | D24: =SLOPE(D2:D13,$B2:$B13)/(STEYX(D2:D13,$B2:$B13)/SQRT(DEVSQ($B2:$B13))) -> 0.36357466 | E24: =SLOPE(E2:E13,$B2:$B13)/(STEYX(E2:E13,$B2:$B13)/SQRT(DEVSQ($B2:$B13))) -> -0.4019292 | F24: =SLOPE(F2:F13,$B2:$B13)/(STEYX(F2:F13,$B2:$B13)/SQRT(DEVSQ($B2:$B13))) -> -1.1457309 | G24: =SLOPE(G2:G13,$B2:$B13)/(STEYX(G2:G13,$B2:$B13)/SQRT(DEVSQ($B2:$B13))) -> 2.2314278 | H24: =SLOPE(H2:H13,$B2:$B13)/(STEYX(H2:H13,$B2:$B13)/SQRT(DEVSQ($B2:$B13))) -> 0.91327761 | I24: =SLOPE(I2:I13,$B2:$B13)/(STEYX(I2:I13,$B2:$B13)/SQRT(DEVSQ($B2:$B13))) -> 1.0930791 | J24: =SLOPE(J2:J13,$B2:$B13)/(STEYX(J2:J13,$B2:$B13)/SQRT(DEVSQ($B2:$B13))) -> 0.72273729 | ... N24: =SLOPE(N2:N13,$B2:$B13)/(STEYX(N2:N13,$B2:$B13)/SQRT(DEVSQ($B2:$B13))) -> -3.9571167
A25: p_val | C25: =_xlfn.T.DIST.2T(ABS(C24), C23) -> 0.49594938 | D25: =_xlfn.T.DIST.2T(ABS(D24), D23) -> 0.73457667 | E25: =_xlfn.T.DIST.2T(ABS(E24), E23) -> 0.70828611 | F25: =_xlfn.T.DIST.2T(ABS(F24), F23) -> 0.31579303 | G25: =_xlfn.T.DIST.2T(ABS(G24), G23) -> 0.089468953 | H25: =_xlfn.T.DIST.2T(ABS(H24), H23) -> 0.41276436 | I25: =_xlfn.T.DIST.2T(ABS(I24), I23) -> 0.33577437 | J25: =_xlfn.T.DIST.2T(ABS(J24), J23) -> 0.50983943 | ... N25: =_xlfn.T.DIST.2T(ABS(N24), N23) -> 0.016717971
A26: ampl | B26: =MAX(B2:B12)-MIN(B2:B12) -> 0.31897643

Sheet E418_act
A1: WT=E418 | B1: PH50 | C1: size | D1: kd | E1: flexibility | F1: polarity | G1: alpha | H1: beta | I1: bulkiness | J1: surf | K1: h_do | L1: h_ac | M1: b_turn | N1: coil
A2: E | B2: 6.5059635 | C2: =IF(A2="G",size!$B$2,IF(A2="A",size!$B$3,IF(A2="S",size!$B$4,IF(A2="C",size!$B$5,IF(A2="D",size!$B$6,IF(A2="P",size!$B$7,IF(A2="N",size!$B$8,IF(A2="T",size!$B$9,IF(A2="E",size!$B$10,IF(A2="V",size!$B$11,IF(A2="Q",size!$B$12,IF(A2="H",size!$B$13,IF(A2="M",size!$B$14,IF(A2="I",size!$B$15,IF(A2="L",size!$B$16,IF(A2="K",size!$B$17,IF(A2="R",size!$B$18,IF(A2="F",size!$B$19,IF(A2="Y",size!$B$20,IF(A2="W",size!B21,"Please enter the one-letter code of the residue in column A")))))))))))))))))))) -> 138.4 | D2: =IF($A2="G",kd!$B$2,IF($A2="A",kd!$B$3,IF($A2="S",kd!$B$4,IF($A2="C",kd!$B$5,IF($A2="D",kd!$B$6,IF($A2="P",kd!$B$7,IF($A2="N",kd!$B$8,IF($A2="T",kd!$B$9,IF($A2="E",kd!$B$10,IF($A2="V",kd!$B$11,IF($A2="Q",kd!$B$12,IF($A2="H",kd!$B$13,IF($A2="M",kd!$B$14,IF($A2="I",kd!$B$15,IF($A2="L",kd!$B$16,IF($A2="K",kd!$B$17,IF($A2="R",kd!$B$18,IF($A2="F",kd!$B$19,IF($A2="Y",kd!$B$20,IF($A2="W",kd!C21,"Please enter the one-letter code of the residue in column A")))))))))))))))))))) -> -3.5 | E2: =IF($A2="G",flxb!$B$2,IF($A2="A",flxb!$B$3,IF($A2="S",flxb!$B$4,IF($A2="C",flxb!$B$5,IF($A2="D",flxb!$B$6,IF($A2="P",flxb!$B$7,IF($A2="N",flxb!$B$8,IF($A2="T",flxb!$B$9,IF($A2="E",flxb!$B$10,IF($A2="V",flxb!$B$11,IF($A2="Q",flxb!$B$12,IF($A2="H",flxb!$B$13,IF($A2="M",flxb!$B$14,IF($A2="I",flxb!$B$15,IF($A2="L",flxb!$B$16,IF($A2="K",flxb!$B$17,IF($A2="R",flxb!$B$18,IF($A2="F",flxb!$B$19,IF($A2="Y",flxb!$B$20,IF($A2="W",flxb!D21,"Please enter the one-letter code of the residue in column A")))))))))))))))))))) -> 0.5 | F2: =IF($A2="G",pol!$B$2,IF($A2="A",pol!$B$3,IF($A2="S",pol!$B$4,IF($A2="C",pol!$B$5,IF($A2="D",pol!$B$6,IF($A2="P",pol!$B$7,IF($A2="N",pol!$B$8,IF($A2="T",pol!$B$9,IF($A2="E",pol!$B$10,IF($A2="V",pol!$B$11,IF($A2="Q",pol!$B$12,IF($A2="H",pol!$B$13,IF($A2="M",pol!$B$14,IF($A2="I",pol!$B$15,IF($A2="L",pol!$B$16,IF($A2="K",pol!$B$17,IF($A2="R",pol!$B$18,IF($A2="F",pol!$B$19,IF($A2="Y",pol!$B$20,IF($A2="W",pol!E21,"Please enter the one-letter code of the residue in column A")))))))))))))))))))) -> 12.3 | G2: =IF($A2="G",alpha_hx!$B$2,IF($A2="A",alpha_hx!$B$3,IF($A2="S",alpha_hx!$B$4,IF($A2="C",alpha_hx!$B$5,IF($A2="D",alpha_hx!$B$6,IF($A2="P",alpha_hx!$B$7,IF($A2="N",alpha_hx!$B$8,IF($A2="T",alpha_hx!$B$9,IF($A2="E",alpha_hx!$B$10,IF($A2="V",alpha_hx!$B$11,IF($A2="Q",alpha_hx!$B$12,IF($A2="H",alpha_hx!$B$13,IF($A2="M",alpha_hx!$B$14,IF($A2="I",alpha_hx!$B$15,IF($A2="L",alpha_hx!$B$16,IF($A2="K",alpha_hx!$B$17,IF($A2="R",alpha_hx!$B$18,IF($A2="F",alpha_hx!$B$19,IF($A2="Y",alpha_hx!$B$20,IF($A2="W",alpha_hx!F21,"Please enter the one-letter code of the residue in column A")))))))))))))))))))) -> 1.504 | H2: =IF($A2="G",beta!$B$2,IF($A2="A",beta!$B$3,IF($A2="S",beta!$B$4,IF($A2="C",beta!$B$5,IF($A2="D",beta!$B$6,IF($A2="P",beta!$B$7,IF($A2="N",beta!$B$8,IF($A2="T",beta!$B$9,IF($A2="E",beta!$B$10,IF($A2="V",beta!$B$11,IF($A2="Q",beta!$B$12,IF($A2="H",beta!$B$13,IF($A2="M",beta!$B$14,IF($A2="I",beta!$B$15,IF($A2="L",beta!$B$16,IF($A2="K",beta!$B$17,IF($A2="R",beta!$B$18,IF($A2="F",beta!$B$19,IF($A2="Y",beta!$B$20,IF($A2="W",beta!G21,"Please enter the one-letter code of the residue in column A")))))))))))))))))))) -> 0.567 | I2: =IF($A2="G",bulky!$B$2,IF($A2="A",bulky!$B$3,IF($A2="S",bulky!$B$4,IF($A2="C",bulky!$B$5,IF($A2="D",bulky!$B$6,IF($A2="P",bulky!$B$7,IF($A2="N",bulky!$B$8,IF($A2="T",bulky!$B$9,IF($A2="E",bulky!$B$10,IF($A2="V",bulky!$B$11,IF($A2="Q",bulky!$B$12,IF($A2="H",bulky!$B$13,IF($A2="M",bulky!$B$14,IF($A2="I",bulky!$B$15,IF($A2="L",bulky!$B$16,IF($A2="K",bulky!$B$17,IF($A2="R",bulky!$B$18,IF($A2="F",bulky!$B$19,IF($A2="Y",bulky!$B$20,IF($A2="W",bulky!H21,"Please enter the one-letter code of the residue in column A")))))))))))))))))))) -> 13.57 | J2: =IF($A2="G",surf!$B$2,IF($A2="A",surf!$B$3,IF($A2="S",surf!$B$4,IF($A2="C",surf!$B$5,IF($A2="D",surf!$B$6,IF($A2="P",surf!$B$7,IF($A2="N",surf!$B$8,IF($A2="T",surf!$B$9,IF($A2="E",surf!$B$10,IF($A2="V",surf!$B$11,IF($A2="Q",surf!$B$12,IF($A2="H",surf!$B$13,IF($A2="M",surf!$B$14,IF($A2="I",surf!$B$15,IF($A2="L",surf!$B$16,IF($A2="K",surf!$B$17,IF($A2="R",surf!$B$18,IF($A2="F",surf!$B$19,IF($A2="Y",surf!$B$20,IF($A2="W",surf!I21,"Please enter the one-letter code of the residue in column A")))))))))))))))))))) -> 190 | K2: =IF($A2="G",h_do!$B$2,IF($A2="A",h_do!$B$3,IF($A2="S",h_do!$B$4,IF($A2="C",h_do!$B$5,IF($A2="D",h_do!$B$6,IF($A2="P",h_do!$B$7,IF($A2="N",h_do!$B$8,IF($A2="T",h_do!$B$9,IF($A2="E",h_do!$B$10,IF($A2="V",h_do!$B$11,IF($A2="Q",h_do!$B$12,IF($A2="H",h_do!$B$13,IF($A2="M",h_do!$B$14,IF($A2="I",h_do!$B$15,IF($A2="L",h_do!$B$16,IF($A2="K",h_do!$B$17,IF($A2="R",h_do!$B$18,IF($A2="F",h_do!$B$19,IF($A2="Y",h_do!$B$20,IF($A2="W",h_do!J21,"Please enter the one-letter code of the residue in column A")))))))))))))))))))) -> 0 | L2: =IF($A2="G",h_ac!$B$2,IF($A2="A",h_ac!$B$3,IF($A2="S",h_ac!$B$4,IF($A2="C",h_ac!$B$5,IF($A2="D",h_ac!$B$6,IF($A2="P",h_ac!$B$7,IF($A2="N",h_ac!$B$8,IF($A2="T",h_ac!$B$9,IF($A2="E",h_ac!$B$10,IF($A2="V",h_ac!$B$11,IF($A2="Q",h_ac!$B$12,IF($A2="H",h_ac!$B$13,IF($A2="M",h_ac!$B$14,IF($A2="I",h_ac!$B$15,IF($A2="L",h_ac!$B$16,IF($A2="K",h_ac!$B$17,IF($A2="R",h_ac!$B$18,IF($A2="F",h_ac!$B$19,IF($A2="Y",h_ac!$B$20,IF($A2="W",h_ac!K21,"Please enter the one-letter code of the residue in column A")))))))))))))))))))) -> 4 | M2: =IF($A2="G",b_turn!$B$2,IF($A2="A",b_turn!$B$3,IF($A2="S",b_turn!$B$4,IF($A2="C",b_turn!$B$5,IF($A2="D",b_turn!$B$6,IF($A2="P",b_turn!$B$7,IF($A2="N",b_turn!$B$8,IF($A2="T",b_turn!$B$9,IF($A2="E",b_turn!$B$10,IF($A2="V",b_turn!$B$11,IF($A2="Q",b_turn!$B$12,IF($A2="H",b_turn!$B$13,IF($A2="M",b_turn!$B$14,IF($A2="I",b_turn!$B$15,IF($A2="L",b_turn!$B$16,IF($A2="K",b_turn!$B$17,IF($A2="R",b_turn!$B$18,IF($A2="F",b_turn!$B$19,IF($A2="Y",b_turn!$B$20,IF($A2="W",b_turn!L21,"Please enter the one-letter code of the residue in column A")))))))))))))))))))) -> 1.149 | N2: =IF($A2="G",coil!$B$2,IF($A2="A",coil!$B$3,IF($A2="S",coil!$B$4,IF($A2="C",coil!$B$5,IF($A2="D",coil!$B$6,IF($A2="P",coil!$B$7,IF($A2="N",coil!$B$8,IF($A2="T",coil!$B$9,IF($A2="E",coil!$B$10,IF($A2="V",coil!$B$11,IF($A2="Q",coil!$B$12,IF($A2="H",coil!$B$13,IF($A2="M",coil!$B$14,IF($A2="I",coil!$B$15,IF($A2="L",coil!$B$16,IF($A2="K",coil!$B$17,IF($A2="R",coil!$B$18,IF($A2="F",coil!$B$19,IF($A2="Y",coil!$B$20,IF($A2="W",coil!M21,"Please enter the one-letter code of the residue in column A")))))))))))))))))))) -> 0.761
A3: Q | B3: 6.0184286 | C3: =IF(A3="G",size!$B$2,IF(A3="A",size!$B$3,IF(A3="S",size!$B$4,IF(A3="C",size!$B$5,IF(A3="D",size!$B$6,IF(A3="P",size!$B$7,IF(A3="N",size!$B$8,IF(A3="T",size!$B$9,IF(A3="E",size!$B$10,IF(A3="V",size!$B$11,IF(A3="Q",size!$B$12,IF(A3="H",size!$B$13,IF(A3="M",size!$B$14,IF(A3="I",size!$B$15,IF(A3="L",size!$B$16,IF(A3="K",size!$B$17,IF(A3="R",size!$B$18,IF(A3="F",size!$B$19,IF(A3="Y",size!$B$20,IF(A3="W",size!B22,"Please enter the one-letter code of the residue in column A")))))))))))))))))))) -> 143.8 | D3: =IF($A3="G",kd!$B$2,IF($A3="A",kd!$B$3,IF($A3="S",kd!$B$4,IF($A3="C",kd!$B$5,IF($A3="D",kd!$B$6,IF($A3="P",kd!$B$7,IF($A3="N",kd!$B$8,IF($A3="T",kd!$B$9,IF($A3="E",kd!$B$10,IF($A3="V",kd!$B$11,IF($A3="Q",kd!$B$12,IF($A3="H",kd!$B$13,IF($A3="M",kd!$B$14,IF($A3="I",kd!$B$15,IF($A3="L",kd!$B$16,IF($A3="K",kd!$B$17,IF($A3="R",kd!$B$18,IF($A3="F",kd!$B$19,IF($A3="Y",kd!$B$20,IF($A3="W",kd!C22,"Please enter the one-letter code of the residue in column A")))))))))))))))))))) -> -3.5 | E3: =IF($A3="G",flxb!$B$2,IF($A3="A",flxb!$B$3,IF($A3="S",flxb!$B$4,IF($A3="C",flxb!$B$5,IF($A3="D",flxb!$B$6,IF($A3="P",flxb!$B$7,IF($A3="N",flxb!$B$8,IF($A3="T",flxb!$B$9,IF($A3="E",flxb!$B$10,IF($A3="V",flxb!$B$11,IF($A3="Q",flxb!$B$12,IF($A3="H",flxb!$B$13,IF($A3="M",flxb!$B$14,IF($A3="I",flxb!$B$15,IF($A3="L",flxb!$B$16,IF($A3="K",flxb!$B$17,IF($A3="R",flxb!$B$18,IF($A3="F",flxb!$B$19,IF($A3="Y",flxb!$B$20,IF($A3="W",flxb!D22,"Please enter the one-letter code of the residue in column A")))))))))))))))))))) -> 0.49 | F3: =IF($A3="G",pol!$B$2,IF($A3="A",pol!$B$3,IF($A3="S",pol!$B$4,IF($A3="C",pol!$B$5,IF($A3="D",pol!$B$6,IF($A3="P",pol!$B$7,IF($A3="N",pol!$B$8,IF($A3="T",pol!$B$9,IF($A3="E",pol!$B$10,IF($A3="V",pol!$B$11,IF($A3="Q",pol!$B$12,IF($A3="H",pol!$B$13,IF($A3="M",pol!$B$14,IF($A3="I",pol!$B$15,IF($A3="L",pol!$B$16,IF($A3="K",pol!$B$17,IF($A3="R",pol!$B$18,IF($A3="F",pol!$B$19,IF($A3="Y",pol!$B$20,IF($A3="W",pol!E22,"Please enter the one-letter code of the residue in column A")))))))))))))))))))) -> 10.5 | G3: =IF($A3="G",alpha_hx!$B$2,IF($A3="A",alpha_hx!$B$3,IF($A3="S",alpha_hx!$B$4,IF($A3="C",alpha_hx!$B$5,IF($A3="D",alpha_hx!$B$6,IF($A3="P",alpha_hx!$B$7,IF($A3="N",alpha_hx!$B$8,IF($A3="T",alpha_hx!$B$9,IF($A3="E",alpha_hx!$B$10,IF($A3="V",alpha_hx!$B$11,IF($A3="Q",alpha_hx!$B$12,IF($A3="H",alpha_hx!$B$13,IF($A3="M",alpha_hx!$B$14,IF($A3="I",alpha_hx!$B$15,IF($A3="L",alpha_hx!$B$16,IF($A3="K",alpha_hx!$B$17,IF($A3="R",alpha_hx!$B$18,IF($A3="F",alpha_hx!$B$19,IF($A3="Y",alpha_hx!$B$20,IF($A3="W",alpha_hx!F22,"Please enter the one-letter code of the residue in column A")))))))))))))))))))) -> 1.164 | H3: =IF($A3="G",beta!$B$2,IF($A3="A",beta!$B$3,IF($A3="S",beta!$B$4,IF($A3="C",beta!$B$5,IF($A3="D",beta!$B$6,IF($A3="P",beta!$B$7,IF($A3="N",beta!$B$8,IF($A3="T",beta!$B$9,IF($A3="E",beta!$B$10,IF($A3="V",beta!$B$11,IF($A3="Q",beta!$B$12,IF($A3="H",beta!$B$13,IF($A3="M",beta!$B$14,IF($A3="I",beta!$B$15,IF($A3="L",beta!$B$16,IF($A3="K",beta!$B$17,IF($A3="R",beta!$B$18,IF($A3="F",beta!$B$19,IF($A3="Y",beta!$B$20,IF($A3="W",beta!G22,"Please enter the one-letter code of the residue in column A")))))))))))))))))))) -> 0.84 | I3: =IF($A3="G",bulky!$B$2,IF($A3="A",bulky!$B$3,IF($A3="S",bulky!$B$4,IF($A3="C",bulky!$B$5,IF($A3="D",bulky!$B$6,IF($A3="P",bulky!$B$7,IF($A3="N",bulky!$B$8,IF($A3="T",bulky!$B$9,IF($A3="E",bulky!$B$10,IF($A3="V",bulky!$B$11,IF($A3="Q",bulky!$B$12,IF($A3="H",bulky!$B$13,IF($A3="M",bulky!$B$14,IF($A3="I",bulky!$B$15,IF($A3="L",bulky!$B$16,IF($A3="K",bulky!$B$17,IF($A3="R",bulky!$B$18,IF($A3="F",bulky!$B$19,IF($A3="Y",bulky!$B$20,IF($A3="W",bulky!H22,"Please enter the one-letter code of the residue in column A")))))))))))))))))))) -> 14.45 | J3: =IF($A3="G",surf!$B$2,IF($A3="A",surf!$B$3,IF($A3="S",surf!$B$4,IF($A3="C",surf!$B$5,IF($A3="D",surf!$B$6,IF($A3="P",surf!$B$7,IF($A3="N",surf!$B$8,IF($A3="T",surf!$B$9,IF($A3="E",surf!$B$10,IF($A3="V",surf!$B$11,IF($A3="Q",surf!$B$12,IF($A3="H",surf!$B$13,IF($A3="M",surf!$B$14,IF($A3="I",surf!$B$15,IF($A3="L",surf!$B$16,IF($A3="K",surf!$B$17,IF($A3="R",surf!$B$18,IF($A3="F",surf!$B$19,IF($A3="Y",surf!$B$20,IF($A3="W",surf!I22,"Please enter the one-letter code of the residue in column A")))))))))))))))))))) -> 180 | K3: =IF($A3="G",h_do!$B$2,IF($A3="A",h_do!$B$3,IF($A3="S",h_do!$B$4,IF($A3="C",h_do!$B$5,IF($A3="D",h_do!$B$6,IF($A3="P",h_do!$B$7,IF($A3="N",h_do!$B$8,IF($A3="T",h_do!$B$9,IF($A3="E",h_do!$B$10,IF($A3="V",h_do!$B$11,IF($A3="Q",h_do!$B$12,IF($A3="H",h_do!$B$13,IF($A3="M",h_do!$B$14,IF($A3="I",h_do!$B$15,IF($A3="L",h_do!$B$16,IF($A3="K",h_do!$B$17,IF($A3="R",h_do!$B$18,IF($A3="F",h_do!$B$19,IF($A3="Y",h_do!$B$20,IF($A3="W",h_do!J22,"Please enter the one-letter code of the residue in column A")))))))))))))))))))) -> 2 | L3: =IF($A3="G",h_ac!$B$2,IF($A3="A",h_ac!$B$3,IF($A3="S",h_ac!$B$4,IF($A3="C",h_ac!$B$5,IF($A3="D",h_ac!$B$6,IF($A3="P",h_ac!$B$7,IF($A3="N",h_ac!$B$8,IF($A3="T",h_ac!$B$9,IF($A3="E",h_ac!$B$10,IF($A3="V",h_ac!$B$11,IF($A3="Q",h_ac!$B$12,IF($A3="H",h_ac!$B$13,IF($A3="M",h_ac!$B$14,IF($A3="I",h_ac!$B$15,IF($A3="L",h_ac!$B$16,IF($A3="K",h_ac!$B$17,IF($A3="R",h_ac!$B$18,IF($A3="F",h_ac!$B$19,IF($A3="Y",h_ac!$B$20,IF($A3="W",h_ac!K22,"Please enter the one-letter code of the residue in column A")))))))))))))))))))) -> 2 | M3: =IF($A3="G",b_turn!$B$2,IF($A3="A",b_turn!$B$3,IF($A3="S",b_turn!$B$4,IF($A3="C",b_turn!$B$5,IF($A3="D",b_turn!$B$6,IF($A3="P",b_turn!$B$7,IF($A3="N",b_turn!$B$8,IF($A3="T",b_turn!$B$9,IF($A3="E",b_turn!$B$10,IF($A3="V",b_turn!$B$11,IF($A3="Q",b_turn!$B$12,IF($A3="H",b_turn!$B$13,IF($A3="M",b_turn!$B$14,IF($A3="I",b_turn!$B$15,IF($A3="L",b_turn!$B$16,IF($A3="K",b_turn!$B$17,IF($A3="R",b_turn!$B$18,IF($A3="F",b_turn!$B$19,IF($A3="Y",b_turn!$B$20,IF($A3="W",b_turn!L22,"Please enter the one-letter code of the residue in column A")))))))))))))))))))) -> 0.997 | N3: =IF($A3="G",coil!$B$2,IF($A3="A",coil!$B$3,IF($A3="S",coil!$B$4,IF($A3="C",coil!$B$5,IF($A3="D",coil!$B$6,IF($A3="P",coil!$B$7,IF($A3="N",coil!$B$8,IF($A3="T",coil!$B$9,IF($A3="E",coil!$B$10,IF($A3="V",coil!$B$11,IF($A3="Q",coil!$B$12,IF($A3="H",coil!$B$13,IF($A3="M",coil!$B$14,IF($A3="I",coil!$B$15,IF($A3="L",coil!$B$16,IF($A3="K",coil!$B$17,IF($A3="R",coil!$B$18,IF($A3="F",coil!$B$19,IF($A3="Y",coil!$B$20,IF($A3="W",coil!M22,"Please enter the one-letter code of the residue in column A")))))))))))))))))))) -> 0.947
